2020-10-11 12:08:13,690	INFO services.py:1164 -- View the Ray dashboard at [1m[32mhttp://127.0.0.1:8265[39m[22m
== Status ==
Memory usage on this node: 11.5/754.6 GiB
Using FIFO scheduling algorithm.
Resources requested: 80/80 CPUs, 1/3 GPUs, 0.0/558.35 GiB heap, 0.0/128.52 GiB objects (0/1.0 accelerator_type:RTX)
Result logdir: /root/ray_results/ppo-jss
Number of trials: 1 (1 RUNNING)
+-------------------------+----------+-------+
| Trial name              | status   | loc   |
|-------------------------+----------+-------|
| PPO_jss_env_70d64_00000 | RUNNING  |       |
+-------------------------+----------+-------+


[2m[36m(pid=507)[0m F1011 12:08:15.883498   507   507 service_based_gcs_client.cc:207] Couldn't reconnect to GCS server. The last attempted GCS server address was 172.17.0.4:42941
[2m[36m(pid=507)[0m *** Check failure stack trace: ***
[2m[36m(pid=507)[0m     @     0x7fda9ecff6ed  google::LogMessage::Fail()
[2m[36m(pid=507)[0m     @     0x7fda9ed0084c  google::LogMessage::SendToLog()
[2m[36m(pid=515)[0m F1011 12:08:15.883437   515   515 service_based_gcs_client.cc:207] Couldn't reconnect to GCS server. The last attempted GCS server address was 172.17.0.4:42941
[2m[36m(pid=515)[0m *** Check failure stack trace: ***
[2m[36m(pid=515)[0m     @     0x7fb0c6db56ed  google::LogMessage::Fail()
[2m[36m(pid=515)[0m     @     0x7fb0c6db684c  google::LogMessage::SendToLog()
[2m[36m(pid=515)[0m     @     0x7fb0c6db53c9  google::LogMessage::Flush()
[2m[36m(pid=515)[0m     @     0x7fb0c6db55e1  google::LogMessage::~LogMessage()
[2m[36m(pid=507)[0m     @     0x7fda9ecff3c9  google::LogMessage::Flush()
[2m[36m(pid=507)[0m     @     0x7fda9ecff5e1  google::LogMessage::~LogMessage()
[2m[36m(pid=507)[0m     @     0x7fda9ecb6789  ray::RayLog::~RayLog()
[2m[36m(pid=515)[0m     @     0x7fb0c6d6c789  ray::RayLog::~RayLog()
[2m[36m(pid=507)[0m     @     0x7fda9e9fa1ea  ray::gcs::ServiceBasedGcsClient::ReconnectGcsServer()
[2m[36m(pid=507)[0m     @     0x7fda9e9fa2ef  ray::gcs::ServiceBasedGcsClient::GcsServiceFailureDetected()
[2m[36m(pid=515)[0m     @     0x7fb0c6ab01ea  ray::gcs::ServiceBasedGcsClient::ReconnectGcsServer()
[2m[36m(pid=515)[0m     @     0x7fb0c6ab02ef  ray::gcs::ServiceBasedGcsClient::GcsServiceFailureDetected()
[2m[36m(pid=507)[0m     @     0x7fda9e9fa491  ray::gcs::ServiceBasedGcsClient::PeriodicallyCheckGcsServerAddress()
[2m[36m(pid=507)[0m     @     0x7fda9e9fc801  ray::gcs::ServiceBasedGcsClient::Connect()
[2m[36m(pid=515)[0m     @     0x7fb0c6ab0491  ray::gcs::ServiceBasedGcsClient::PeriodicallyCheckGcsServerAddress()
[2m[36m(pid=515)[0m     @     0x7fb0c6ab2801  ray::gcs::ServiceBasedGcsClient::Connect()
[2m[36m(pid=507)[0m     @     0x7fda9e90b7a8  ray::gcs::GlobalStateAccessor::Connect()
[2m[36m(pid=507)[0m     @     0x7fda9e87ca2c  __pyx_pw_3ray_7_raylet_19GlobalStateAccessor_3connect()
[2m[36m(pid=507)[0m     @     0x5602315a698a  method_vectorcall_NOARGS
[2m[36m(pid=507)[0m     @     0x560231536b08  _PyEval_EvalFrameDefault.cold.2792
[2m[36m(pid=507)[0m     @     0x5602315c16a2  _PyEval_EvalCodeWithName
[2m[36m(pid=507)[0m     @     0x5602315c2a20  method_vectorcall
[2m[36m(pid=515)[0m     @     0x7fb0c69c17a8  ray::gcs::GlobalStateAccessor::Connect()
[2m[36m(pid=515)[0m     @     0x7fb0c6932a2c  __pyx_pw_3ray_7_raylet_19GlobalStateAccessor_3connect()
[2m[36m(pid=515)[0m     @     0x555d8337898a  method_vectorcall_NOARGS
[2m[36m(pid=515)[0m     @     0x555d83308b08  _PyEval_EvalFrameDefault.cold.2792
[2m[36m(pid=515)[0m     @     0x555d833936a2  _PyEval_EvalCodeWithName
[2m[36m(pid=515)[0m     @     0x555d83394a20  method_vectorcall
[2m[36m(pid=515)[0m     @     0x555d83309de6  _PyEval_EvalFrameDefault.cold.2792
[2m[36m(pid=515)[0m     @     0x555d83393baf  _PyEval_EvalCodeWithName
[2m[36m(pid=515)[0m     @     0x555d83394643  _PyFunction_Vectorcall.localalias.353
[2m[36m(pid=507)[0m     @     0x560231537de6  _PyEval_EvalFrameDefault.cold.2792
[2m[36m(pid=507)[0m     @     0x5602315c1baf  _PyEval_EvalCodeWithName
[2m[36m(pid=507)[0m     @     0x5602315c2643  _PyFunction_Vectorcall.localalias.353
[2m[36m(pid=507)[0m     @     0x560231537de6  _PyEval_EvalFrameDefault.cold.2792
[2m[36m(pid=507)[0m     @     0x5602315c16a2  _PyEval_EvalCodeWithName
[2m[36m(pid=507)[0m     @     0x5602315c2454  PyEval_EvalCodeEx
[2m[36m(pid=507)[0m     @     0x560231650bbc  PyEval_EvalCode
[2m[36m(pid=507)[0m     @     0x560231650c64  run_eval_code_obj
[2m[36m(pid=507)[0m     @     0x560231682d14  run_mod
[2m[36m(pid=507)[0m     @     0x56023154b625  PyRun_FileExFlags
[2m[36m(pid=507)[0m     @     0x56023154ba0a  PyRun_SimpleFileExFlags
[2m[36m(pid=507)[0m     @     0x56023154c8cf  Py_RunMain.cold.2911
[2m[36m(pid=507)[0m     @     0x560231685829  Py_BytesMain
[2m[36m(pid=507)[0m     @     0x7fdaa0004840  __libc_start_main
[2m[36m(pid=507)[0m     @     0x560231615b33  (unknown)
[2m[36m(pid=515)[0m     @     0x555d83309de6  _PyEval_EvalFrameDefault.cold.2792
[2m[36m(pid=515)[0m     @     0x555d833936a2  _PyEval_EvalCodeWithName
[2m[36m(pid=515)[0m     @     0x555d83394454  PyEval_EvalCodeEx
[2m[36m(pid=515)[0m     @     0x555d83422bbc  PyEval_EvalCode
[2m[36m(pid=515)[0m     @     0x555d83422c64  run_eval_code_obj
[2m[36m(pid=515)[0m     @     0x555d83454d14  run_mod
[2m[36m(pid=515)[0m     @     0x555d8331d625  PyRun_FileExFlags
[2m[36m(pid=515)[0m     @     0x555d8331da0a  PyRun_SimpleFileExFlags
[2m[36m(pid=515)[0m     @     0x555d8331e8cf  Py_RunMain.cold.2911
[2m[36m(pid=515)[0m     @     0x555d83457829  Py_BytesMain
[2m[36m(pid=515)[0m     @     0x7fb0c80ba840  __libc_start_main
[2m[36m(pid=515)[0m     @     0x555d833e7b33  (unknown)
[2m[33m(pid=raylet)[0m E1011 12:08:16.047902   378   378 node_manager.cc:3307] Failed to send get core worker stats request: IOError: 14: Connection reset by peer
[2m[33m(pid=raylet)[0m E1011 12:08:16.048079   378   378 node_manager.cc:3307] Failed to send get core worker stats request: IOError: 14: Connection reset by peer
[2m[36m(pid=545)[0m 2020-10-11 12:08:16,445	INFO trainer.py:616 -- Current log_level is WARN. For more information, set 'log_level': 'INFO' / 'DEBUG' or use the -v and -vv flags.
2020-10-11 12:08:21,708	ERROR trial_runner.py:567 -- Trial PPO_jss_env_70d64_00000: Error processing event.
Traceback (most recent call last):
  File "/root/miniconda3/lib/python3.8/site-packages/ray/tune/trial_runner.py", line 515, in _process_trial
    result = self.trial_executor.fetch_result(trial)
  File "/root/miniconda3/lib/python3.8/site-packages/ray/tune/ray_trial_executor.py", line 488, in fetch_result
    result = ray.get(trial_future[0], timeout=DEFAULT_GET_TIMEOUT)
  File "/root/miniconda3/lib/python3.8/site-packages/ray/worker.py", line 1428, in get
    raise value.as_instanceof_cause()
ray.exceptions.RayTaskError(ValueError): [36mray::PPO.train()[39m (pid=545, ip=172.17.0.4)
  File "python/ray/_raylet.pyx", line 445, in ray._raylet.execute_task
  File "python/ray/_raylet.pyx", line 479, in ray._raylet.execute_task
  File "python/ray/_raylet.pyx", line 483, in ray._raylet.execute_task
  File "python/ray/_raylet.pyx", line 484, in ray._raylet.execute_task
  File "python/ray/_raylet.pyx", line 438, in ray._raylet.execute_task.function_executor
  File "/root/miniconda3/lib/python3.8/site-packages/ray/rllib/agents/trainer_template.py", line 101, in __init__
    Trainer.__init__(self, config, env, logger_creator)
  File "/root/miniconda3/lib/python3.8/site-packages/ray/rllib/agents/trainer.py", line 476, in __init__
    super().__init__(config, logger_creator)
  File "/root/miniconda3/lib/python3.8/site-packages/ray/tune/trainable.py", line 249, in __init__
    self.setup(copy.deepcopy(self.config))
  File "/root/miniconda3/lib/python3.8/site-packages/ray/rllib/agents/trainer.py", line 629, in setup
    self._init(self.config, self.env_creator)
  File "/root/miniconda3/lib/python3.8/site-packages/ray/rllib/agents/trainer_template.py", line 123, in _init
    self.workers = self._make_workers(env_creator, self._policy_class,
  File "/root/miniconda3/lib/python3.8/site-packages/ray/rllib/agents/trainer.py", line 694, in _make_workers
    return WorkerSet(
  File "/root/miniconda3/lib/python3.8/site-packages/ray/rllib/evaluation/worker_set.py", line 72, in __init__
    self._local_worker = self._make_worker(RolloutWorker, env_creator,
  File "/root/miniconda3/lib/python3.8/site-packages/ray/rllib/evaluation/worker_set.py", line 268, in _make_worker
    worker = cls(
  File "/root/miniconda3/lib/python3.8/site-packages/ray/rllib/evaluation/rollout_worker.py", line 484, in __init__
    raise ValueError("Unsupported batch mode: {}".format(
ValueError: Unsupported batch mode: truncated_episodes
== Status ==
Memory usage on this node: 24.2/754.6 GiB
Using FIFO scheduling algorithm.
Resources requested: 0/80 CPUs, 0/3 GPUs, 0.0/558.35 GiB heap, 0.0/128.52 GiB objects (0/1.0 accelerator_type:RTX)
Result logdir: /root/ray_results/ppo-jss
Number of trials: 1 (1 ERROR)
+-------------------------+----------+-------+
| Trial name              | status   | loc   |
|-------------------------+----------+-------|
| PPO_jss_env_70d64_00000 | ERROR    |       |
+-------------------------+----------+-------+
Number of errored trials: 1
+-------------------------+--------------+-----------------------------------------------------------------------------------+
| Trial name              |   # failures | error file                                                                        |
|-------------------------+--------------+-----------------------------------------------------------------------------------|
| PPO_jss_env_70d64_00000 |            1 | /root/ray_results/ppo-jss/PPO_jss_env_70d64_00000_0_2020-10-11_12-08-15/error.txt |
+-------------------------+--------------+-----------------------------------------------------------------------------------+

== Status ==
Memory usage on this node: 24.2/754.6 GiB
Using FIFO scheduling algorithm.
Resources requested: 0/80 CPUs, 0/3 GPUs, 0.0/558.35 GiB heap, 0.0/128.52 GiB objects (0/1.0 accelerator_type:RTX)
Result logdir: /root/ray_results/ppo-jss
Number of trials: 1 (1 ERROR)
+-------------------------+----------+-------+
| Trial name              | status   | loc   |
|-------------------------+----------+-------|
| PPO_jss_env_70d64_00000 | ERROR    |       |
+-------------------------+----------+-------+
Number of errored trials: 1
+-------------------------+--------------+-----------------------------------------------------------------------------------+
| Trial name              |   # failures | error file                                                                        |
|-------------------------+--------------+-----------------------------------------------------------------------------------|
| PPO_jss_env_70d64_00000 |            1 | /root/ray_results/ppo-jss/PPO_jss_env_70d64_00000_0_2020-10-11_12-08-15/error.txt |
+-------------------------+--------------+-----------------------------------------------------------------------------------+

Traceback (most recent call last):
  File "train.py", line 72, in <module>
    train_func()
  File "train.py", line 56, in train_func
    analysis = tune.run(PPOTrainer, config=config, stop=stop, name="ppo-jss")
  File "/root/miniconda3/lib/python3.8/site-packages/ray/tune/tune.py", line 427, in run
    raise TuneError("Trials did not complete", incomplete_trials)
ray.tune.error.TuneError: ('Trials did not complete', [PPO_jss_env_70d64_00000])
