2020-10-12 12:22:43,378	INFO services.py:1164 -- View the Ray dashboard at [1m[32mhttp://127.0.0.1:8265[39m[22m
== Status ==
Memory usage on this node: 11.5/754.6 GiB
Using FIFO scheduling algorithm.
Resources requested: 80/80 CPUs, 1/3 GPUs, 0.0/557.71 GiB heap, 0.0/128.52 GiB objects (0/1.0 accelerator_type:RTX)
Result logdir: /root/ray_results/ppo-jss
Number of trials: 1 (1 RUNNING)
+-------------------------+----------+-------+
| Trial name              | status   | loc   |
|-------------------------+----------+-------|
| PPO_jss_env_a197e_00000 | RUNNING  |       |
+-------------------------+----------+-------+


[2m[36m(pid=46184)[0m 2020-10-12 12:22:46,161	INFO trainer.py:616 -- Current log_level is WARN. For more information, set 'log_level': 'INFO' / 'DEBUG' or use the -v and -vv flags.
2020-10-12 12:22:46,869	ERROR trial_runner.py:567 -- Trial PPO_jss_env_a197e_00000: Error processing event.
Traceback (most recent call last):
  File "/root/miniconda3/lib/python3.8/site-packages/ray/tune/trial_runner.py", line 515, in _process_trial
    result = self.trial_executor.fetch_result(trial)
  File "/root/miniconda3/lib/python3.8/site-packages/ray/tune/ray_trial_executor.py", line 488, in fetch_result
    result = ray.get(trial_future[0], timeout=DEFAULT_GET_TIMEOUT)
  File "/root/miniconda3/lib/python3.8/site-packages/ray/worker.py", line 1428, in get
    raise value.as_instanceof_cause()
ray.exceptions.RayTaskError(FileNotFoundError): [36mray::PPO.train()[39m (pid=46184, ip=172.17.0.4)
  File "python/ray/_raylet.pyx", line 445, in ray._raylet.execute_task
  File "python/ray/_raylet.pyx", line 479, in ray._raylet.execute_task
  File "python/ray/_raylet.pyx", line 483, in ray._raylet.execute_task
  File "python/ray/_raylet.pyx", line 484, in ray._raylet.execute_task
  File "python/ray/_raylet.pyx", line 438, in ray._raylet.execute_task.function_executor
  File "/root/miniconda3/lib/python3.8/site-packages/ray/rllib/agents/trainer_template.py", line 101, in __init__
    Trainer.__init__(self, config, env, logger_creator)
  File "/root/miniconda3/lib/python3.8/site-packages/ray/rllib/agents/trainer.py", line 476, in __init__
    super().__init__(config, logger_creator)
  File "/root/miniconda3/lib/python3.8/site-packages/ray/tune/trainable.py", line 249, in __init__
    self.setup(copy.deepcopy(self.config))
  File "/root/miniconda3/lib/python3.8/site-packages/ray/rllib/agents/trainer.py", line 629, in setup
    self._init(self.config, self.env_creator)
  File "/root/miniconda3/lib/python3.8/site-packages/ray/rllib/agents/trainer_template.py", line 123, in _init
    self.workers = self._make_workers(env_creator, self._policy_class,
  File "/root/miniconda3/lib/python3.8/site-packages/ray/rllib/agents/trainer.py", line 694, in _make_workers
    return WorkerSet(
  File "/root/miniconda3/lib/python3.8/site-packages/ray/rllib/evaluation/worker_set.py", line 72, in __init__
    self._local_worker = self._make_worker(RolloutWorker, env_creator,
  File "/root/miniconda3/lib/python3.8/site-packages/ray/rllib/evaluation/worker_set.py", line 268, in _make_worker
    worker = cls(
  File "/root/miniconda3/lib/python3.8/site-packages/ray/rllib/evaluation/rollout_worker.py", line 332, in __init__
    self.env = _validate_env(env_creator(env_context))
  File "train.py", line 21, in env_creator
    return BestActionsWrapper(JSS(env_config))
  File "/JSS/JSS/env/JSS.py", line 59, in __init__
    instance_file = open(instance_path, 'r')
FileNotFoundError: [Errno 2] No such file or directory: 'env/instances/ta54'
== Status ==
Memory usage on this node: 13.6/754.6 GiB
Using FIFO scheduling algorithm.
Resources requested: 0/80 CPUs, 0/3 GPUs, 0.0/557.71 GiB heap, 0.0/128.52 GiB objects (0/1.0 accelerator_type:RTX)
Result logdir: /root/ray_results/ppo-jss
Number of trials: 1 (1 ERROR)
+-------------------------+----------+-------+
| Trial name              | status   | loc   |
|-------------------------+----------+-------|
| PPO_jss_env_a197e_00000 | ERROR    |       |
+-------------------------+----------+-------+
Number of errored trials: 1
+-------------------------+--------------+-----------------------------------------------------------------------------------+
| Trial name              |   # failures | error file                                                                        |
|-------------------------+--------------+-----------------------------------------------------------------------------------|
| PPO_jss_env_a197e_00000 |            1 | /root/ray_results/ppo-jss/PPO_jss_env_a197e_00000_0_2020-10-12_12-22-44/error.txt |
+-------------------------+--------------+-----------------------------------------------------------------------------------+

Traceback (most recent call last):
  File "train.py", line 74, in <module>
    train_func()
  File "train.py", line 56, in train_func
    analysis = tune.run(PPOTrainer, config=config, stop=stop, name="ppo-jss")
  File "/root/miniconda3/lib/python3.8/site-packages/ray/tune/tune.py", line 427, in run
    raise TuneError("Trials did not complete", incomplete_trials)
ray.tune.error.TuneError: ('Trials did not complete', [PPO_jss_env_a197e_00000])
