2020-10-13 10:35:56,540	INFO services.py:1164 -- View the Ray dashboard at [1m[32mhttp://127.0.0.1:8265[39m[22m
== Status ==
Memory usage on this node: 11.7/754.6 GiB
Using FIFO scheduling algorithm.
Resources requested: 3/80 CPUs, 0/3 GPUs, 0.0/557.18 GiB heap, 0.0/128.52 GiB objects (0/1.0 accelerator_type:RTX)
Result logdir: /root/ray_results/ppo-jss
Number of trials: 1 (1 RUNNING)
+----------------------------------+----------+-------+
| Trial name                       | status   | loc   |
|----------------------------------+----------+-------|
| RandomMasked_jss_env_e13d6_00000 | RUNNING  |       |
+----------------------------------+----------+-------+


2020-10-13 10:35:59,308	ERROR trial_runner.py:567 -- Trial RandomMasked_jss_env_e13d6_00000: Error processing event.
Traceback (most recent call last):
  File "/root/miniconda3/lib/python3.8/site-packages/ray/tune/trial_runner.py", line 515, in _process_trial
    result = self.trial_executor.fetch_result(trial)
  File "/root/miniconda3/lib/python3.8/site-packages/ray/tune/ray_trial_executor.py", line 488, in fetch_result
    result = ray.get(trial_future[0], timeout=DEFAULT_GET_TIMEOUT)
  File "/root/miniconda3/lib/python3.8/site-packages/ray/worker.py", line 1428, in get
    raise value.as_instanceof_cause()
ray.exceptions.RayTaskError: [36mray::RandomMasked.train()[39m (pid=17518, ip=172.17.0.4)
  File "python/ray/_raylet.pyx", line 445, in ray._raylet.execute_task
  File "python/ray/_raylet.pyx", line 479, in ray._raylet.execute_task
  File "python/ray/_raylet.pyx", line 483, in ray._raylet.execute_task
  File "python/ray/_raylet.pyx", line 484, in ray._raylet.execute_task
  File "python/ray/_raylet.pyx", line 438, in ray._raylet.execute_task.function_executor
  File "/root/miniconda3/lib/python3.8/site-packages/ray/rllib/agents/trainer_template.py", line 101, in __init__
    Trainer.__init__(self, config, env, logger_creator)
  File "/root/miniconda3/lib/python3.8/site-packages/ray/rllib/agents/trainer.py", line 476, in __init__
    super().__init__(config, logger_creator)
  File "/root/miniconda3/lib/python3.8/site-packages/ray/tune/trainable.py", line 249, in __init__
    self.setup(copy.deepcopy(self.config))
  File "/root/miniconda3/lib/python3.8/site-packages/ray/rllib/agents/trainer.py", line 577, in setup
    self.config = Trainer.merge_trainer_configs(self._default_config,
  File "/root/miniconda3/lib/python3.8/site-packages/ray/rllib/agents/trainer.py", line 1045, in merge_trainer_configs
    return deep_update(config1, config2, _allow_unknown_configs,
  File "/root/miniconda3/lib/python3.8/site-packages/ray/tune/utils/util.py", line 208, in deep_update
    raise Exception("Unknown config parameter `{}` ".format(k))
Exception: Unknown config parameter `instance_path`
== Status ==
Memory usage on this node: 11.8/754.6 GiB
Using FIFO scheduling algorithm.
Resources requested: 0/80 CPUs, 0/3 GPUs, 0.0/557.18 GiB heap, 0.0/128.52 GiB objects (0/1.0 accelerator_type:RTX)
Result logdir: /root/ray_results/ppo-jss
Number of trials: 1 (1 ERROR)
+----------------------------------+----------+-------+
| Trial name                       | status   | loc   |
|----------------------------------+----------+-------|
| RandomMasked_jss_env_e13d6_00000 | ERROR    |       |
+----------------------------------+----------+-------+
Number of errored trials: 1
+----------------------------------+--------------+--------------------------------------------------------------------------------------------+
| Trial name                       |   # failures | error file                                                                                 |
|----------------------------------+--------------+--------------------------------------------------------------------------------------------|
| RandomMasked_jss_env_e13d6_00000 |            1 | /root/ray_results/ppo-jss/RandomMasked_jss_env_e13d6_00000_0_2020-10-13_10-35-57/error.txt |
+----------------------------------+--------------+--------------------------------------------------------------------------------------------+

Traceback (most recent call last):
  File "random_loop.py", line 66, in <module>
    rand_func()
  File "random_loop.py", line 48, in rand_func
    analysis = tune.run(RandomMaskedTrainer, config=config, stop=stop, name="ppo-jss")
  File "/root/miniconda3/lib/python3.8/site-packages/ray/tune/tune.py", line 427, in run
    raise TuneError("Trials did not complete", incomplete_trials)
ray.tune.error.TuneError: ('Trials did not complete', [RandomMasked_jss_env_e13d6_00000])
